Workbook

Sheet Plans
A1: DronaHost: four-plan lineup
A2: Blue text = a value you can change. Black = formula. Green = pulled from another tab. Yellow = needs your decision or data.
A4: Feature | B4: Starter | C4: Growth | D4: Pro | E4: Scale | F4: Notes
A5: Highlight on the pricing page | C5: Most popular | F5: Only one plan carries the badge.
A6: Best for | B6: A business site and email | C6: Growing business, a few sites | D6: Busy sites and small stores | E6: WooCommerce and heavy traffic
A7: Price
A8: Price per month, billed yearly ($) | B8: 14.99 | C8: 21.99 | D8: 49.99 | E8: 149.99 | F8: Starter, Growth and Scale are from your sheet. Pro is lowered from your $59.99 so the step up from Growth is smaller. For comparison, SiteGround's entry plan renews at $17.99 and Hostinger's at $10.99 (their pricing pages, 11 Oct 2026).
A9: Price per month, billed monthly ($) | B9: =ROUND(B8*(1+$B$37),0)-0.01 -> 18.99 | C9: =ROUND(C8*(1+$B$37),0)-0.01 -> 26.99 | D9: =ROUND(D8*(1+$B$37),0)-0.01 -> 61.99 | E9: =ROUND(E8*(1+$B$37),0)-0.01 -> 186.99 | F9: Yearly price plus the monthly extra below, rounded to end in .99.
A10: Yearly total charged ($) | B10: =B8*12 -> 179.88 | C10: =C8*12 -> 263.88 | D10: =D8*12 -> 599.88 | E10: =E8*12 -> 1799.88 | F10: Price per month x 12.
A11: Price step from the previous tier | B11: n/a | C11: =C8/B8 -> 1.466978 | D11: =D8/C8 -> 2.273306 | E11: =E8/D8 -> 3.0004001 | F11: The last step is larger because Scale moves to dedicated hardware.
A12: What the customer gets
A13: Websites | B13: 2 | C13: 5 | D13: 25 | E13: Unlimited | F13: From your sheet. Your current $1 to $2 plans allow 5 or unlimited sites.
A14: Storage (GB, NVMe) | B14: 50 | C14: 80 | D14: 100 | E14: 150 | F14: From your sheet.
A15: Mailboxes | B15: 10 | C15: 25 | D15: 100 | E15: Unlimited | F15: From your sheet.
A16: Databases | B16: 4 | C16: 10 | D16: 50 | E16: Unlimited | F16: From your sheet.
A17: Daily backups kept (days) | B17: 7 | C17: 14 | D17: 30 | E17: 30 | F17: My suggestion. Your sheet had 1, 7, 7, 7. SiteGround keeps 30 days on every plan (siteground.com, 11 Oct 2026).
A18: Visits per month | B18: TBC | C18: TBC | D18: TBC | E18: TBC | F18: Fill in after a load test on each tier. Show this on the site in place of bandwidth.
A19: Bandwidth (GB per month) | B19: 200 | C19: 500 | D19: 1000 | E19: Unlimited | F19: From your sheet. Keep as an internal limit.
A20: Support | B20: Standard | C20: Priority | D20: 24/7 | E20: 24/7, senior experts | F20: From your sheet. Scale takes the senior-expert support your sheet gave Dedicated Core.
A21: Performance tuning | B21: No | C21: No | D21: Yes | E21: Yes | F21: From your sheet.
A22: Redis | B22: No | C22: No | D22: No | E22: Yes | F22: My suggestion. Your sheet had Redis only on Dedicated Core.
A23: Resources (these drive the PHP settings tab)
A24: Resource type | B24: Shared | C24: Shared | D24: Semi-dedicated | E24: Dedicated | F24: From your sheet.
A25: CPU cores | B25: 2 | C25: 2 | D25: 4 | E25: 8 | F25: From your sheet's CPU % (200, 200, 400, 800). Show cores on the site.
A26: RAM (GB) | B26: 3 | C26: 4 | D26: 6 | E26: 8 | F26: From your sheet.
A27: Included in every plan
A28: Free SSL | B28: Yes | C28: Yes | D28: Yes | E28: Yes
A29: DDoS protection | B29: Yes | C29: Yes | D29: Yes | E29: Yes
A30: Imunify360 security | B30: Yes | C30: Yes | D30: Yes | E30: Yes | F30: Your sheet left these three blank for Scale.
A31: Free migration, done for the customer | B31: Yes | C31: Yes | D31: Yes | E31: Yes | F31: Lead with this and the WordPress expert.
A32: Server monitoring | B32: Yes | C32: Yes | D32: Yes | E32: Yes
A33: No price increase on renewal | B33: Yes | C33: Yes | D33: Yes | E33: Yes | F33: Put this next to the price.
A34: 30-day money-back guarantee | B34: Yes | C34: Yes | D34: Yes | E34: Yes | F34: Already on your site. Keep it next to the order button.
A36: Assumptions
A37: Extra charged for paying monthly | B37: 0.25 | F37: My suggestion. Change it and the monthly prices update.
A39: Above Scale: one 'Talk to us' strip, no plan card
A40: Dedicated Core, from ($ per month) | B40: 300 | F40: From your sheet.
A41: Enterprise | B41: Custom quote | F41: WhatsApp and consultation buttons, no spec table.

Sheet PHP settings
A1: PHP and PHP-FPM settings per plan
A2: Change the blue inputs; the values to set and the checks update. Apply the same values to every PHP version you offer.
A4: Setting | B4: Starter | C4: Growth | D4: Pro | E4: Scale | F4: Notes
A5: Sizing inputs
A6: RAM (GB) | B6: =Plans!B26 -> 3 | C6: =Plans!C26 -> 4 | D6: =Plans!D26 -> 6 | E6: =Plans!E26 -> 8 | F6: From the Plans tab.
A7: CPU cores | B7: =Plans!B25 -> 2 | C7: =Plans!C25 -> 2 | D7: =Plans!D25 -> 4 | E7: =Plans!E25 -> 8 | F7: From the Plans tab.
A8: Share of RAM given to PHP workers | B8: 0.7 | C8: 0.7 | D8: 0.7 | E8: 0.7 | F8: Assumes MySQL and Redis do not count against the same RAM limit. If they do (likely on Scale), lower this to about 50%.
A9: Average RAM per PHP worker (MB) | B9: 80 | C9: 90 | D9: 100 | E9: 110 | F9: My estimate for WordPress, heavier on tiers likely to run WooCommerce. Replace with what your servers actually show.
A10: Most PHP workers per CPU core | B10: 10 | C10: 10 | D10: 10 | E10: 10 | F10: My estimate. Beyond this, extra workers wait for CPU and use RAM without serving pages faster.
A11: Limits you choose
A12: memory_limit (MB) | B12: 512 | C12: 512 | D12: 768 | E12: 1024 | F12: A ceiling per request, not a reservation. Your sheet had 1G to 2G, which lets a single request take a quarter to a third of the plan's RAM.
A13: post_max_size (MB) | B13: 256 | C13: 512 | D13: 512 | E13: 1024 | F13: Must be at least upload_max_filesize, or the smaller value is the real upload limit.
A14: upload_max_filesize (MB) | B14: 256 | C14: 512 | D14: 512 | E14: 1024 | F14: Your sheet had this above post_max_size on every plan.
A15: max_execution_time (seconds) | B15: 120 | C15: 240 | D15: 240 | E15: 300 | F15: From your sheet.
A16: max_input_time (seconds) | B16: 120 | C16: 240 | D16: 240 | E16: 300 | F16: From your sheet.
A17: max_input_vars | B17: 3000 | C17: 5000 | D17: 5000 | E17: 10000 | F17: Not in your sheet. Large WordPress menus and WooCommerce product forms fail at the PHP default of 1000.
A18: pm.max_requests | B18: 300 | C18: 500 | D18: 800 | E18: 1200 | F18: From your sheet.
A19: pm (process manager mode) | B19: ondemand | C19: ondemand | D19: dynamic | E19: dynamic | F19: From your sheet: ondemand on shared tiers frees RAM when a site is idle.
A20: Values to set
A21: memory_limit | B21: =IF(MOD(B12,1024)=0,B12/1024&"G",B12&"M") -> 512M | C21: =IF(MOD(C12,1024)=0,C12/1024&"G",C12&"M") -> 512M | D21: =IF(MOD(D12,1024)=0,D12/1024&"G",D12&"M") -> 768M | E21: =IF(MOD(E12,1024)=0,E12/1024&"G",E12&"M") -> 1G
A22: post_max_size | B22: =IF(MOD(B13,1024)=0,B13/1024&"G",B13&"M") -> 256M | C22: =IF(MOD(C13,1024)=0,C13/1024&"G",C13&"M") -> 512M | D22: =IF(MOD(D13,1024)=0,D13/1024&"G",D13&"M") -> 512M | E22: =IF(MOD(E13,1024)=0,E13/1024&"G",E13&"M") -> 1G
A23: upload_max_filesize | B23: =IF(MOD(B14,1024)=0,B14/1024&"G",B14&"M") -> 256M | C23: =IF(MOD(C14,1024)=0,C14/1024&"G",C14&"M") -> 512M | D23: =IF(MOD(D14,1024)=0,D14/1024&"G",D14&"M") -> 512M | E23: =IF(MOD(E14,1024)=0,E14/1024&"G",E14&"M") -> 1G
A24: max_execution_time | B24: =B15 -> 120 | C24: =C15 -> 240 | D24: =D15 -> 240 | E24: =E15 -> 300
A25: max_input_time | B25: =B16 -> 120 | C25: =C16 -> 240 | D25: =D16 -> 240 | E25: =E16 -> 300
A26: max_input_vars | B26: =B17 -> 3000 | C26: =C17 -> 5000 | D26: =D17 -> 5000 | E26: =E17 -> 10000
A27: opcache.enable | B27: On | C27: On | D27: On | E27: On | F27: From your sheet.
A28: pm | B28: =B19 -> ondemand | C28: =C19 -> ondemand | D28: =D19 -> dynamic | E28: =E19 -> dynamic
A29: pm.max_children | B29: =MIN(INT(B6*1024*B8/B9),B7*B10) -> 20 | C29: =MIN(INT(C6*1024*C8/C9),C7*C10) -> 20 | D29: =MIN(INT(D6*1024*D8/D9),D7*D10) -> 40 | E29: =MIN(INT(E6*1024*E8/E9),E7*E10) -> 52 | F29: The smaller of what RAM allows and what the cores can serve. Your sheet had 10, 25, 60 and 120; 120 workers on Scale would need more RAM than the plan has.
A30: pm.start_servers | B30: =IF(B19="dynamic",MIN(B7*3,B29),"n/a") -> n/a | C30: =IF(C19="dynamic",MIN(C7*3,C29),"n/a") -> n/a | D30: =IF(D19="dynamic",MIN(D7*3,D29),"n/a") -> 12 | E30: =IF(E19="dynamic",MIN(E7*3,E29),"n/a") -> 24 | F30: Dynamic mode only: 3 per core.
A31: pm.min_spare_servers | B31: =IF(B19="dynamic",MIN(B7*2,B29),"n/a") -> n/a | C31: =IF(C19="dynamic",MIN(C7*2,C29),"n/a") -> n/a | D31: =IF(D19="dynamic",MIN(D7*2,D29),"n/a") -> 8 | E31: =IF(E19="dynamic",MIN(E7*2,E29),"n/a") -> 16 | F31: Dynamic mode only: 2 per core.
A32: pm.max_spare_servers | B32: =IF(B19="dynamic",MIN(B7*4,B29),"n/a") -> n/a | C32: =IF(C19="dynamic",MIN(C7*4,C29),"n/a") -> n/a | D32: =IF(D19="dynamic",MIN(D7*4,D29),"n/a") -> 16 | E32: =IF(E19="dynamic",MIN(E7*4,E29),"n/a") -> 32 | F32: Dynamic mode only: 4 per core.
A33: pm.max_requests | B33: =B18 -> 300 | C33: =C18 -> 500 | D33: =D18 -> 800 | E33: =E18 -> 1200
A34: Checks
A35: pm.max_children is limited by | B35: =IF(INT(B6*1024*B8/B9)<=B7*B10,"RAM","CPU cores") -> CPU cores | C35: =IF(INT(C6*1024*C8/C9)<=C7*C10,"RAM","CPU cores") -> CPU cores | D35: =IF(INT(D6*1024*D8/D9)<=D7*D10,"RAM","CPU cores") -> CPU cores | E35: =IF(INT(E6*1024*E8/E9)<=E7*E10,"RAM","CPU cores") -> RAM | F35: Starter and Growth have the same 2 cores, so they get the same worker count.
A36: Typical PHP RAM use at full load (MB) | B36: =B29*B9 -> 1600 | C36: =C29*C9 -> 1800 | D36: =D29*D9 -> 4000 | E36: =E29*E9 -> 5720 | F36: pm.max_children x average worker size.
A37: As a share of plan RAM | B37: =B36/(B6*1024) -> 0.52083333 | C37: =C36/(C6*1024) -> 0.43945312 | D37: =D36/(D6*1024) -> 0.65104167 | E37: =E36/(E6*1024) -> 0.69824219 | F37: Should be at or under the share set above.
A38: post_max_size covers upload_max_filesize | B38: =IF(B13>=B14,"OK","FIX") -> OK | C38: =IF(C13>=C14,"OK","FIX") -> OK | D38: =IF(D13>=D14,"OK","FIX") -> OK | E38: =IF(E13>=E14,"OK","FIX") -> OK
A39: memory_limit covers post_max_size | B39: =IF(B12>=B13,"OK","FIX") -> OK | C39: =IF(C12>=C13,"OK","FIX") -> OK | D39: =IF(D12>=D13,"OK","FIX") -> OK | E39: =IF(E12>=E13,"OK","FIX") -> OK | F39: Equal is fine: uploaded files are written to disk, not held in memory.
A40: Worst case if every worker hits memory_limit (x plan RAM) | B40: =B29*B12/(B6*1024) -> 3.3333333 | C40: =C29*C12/(C6*1024) -> 2.5 | D40: =D29*D12/(D6*1024) -> 5 | E40: =E29*E12/(E6*1024) -> 6.5 | F40: Above 1.0x on any host that shares RAM, so it is a comparison figure, not a pass/fail. Your sheet's Pro (60 workers x 2G on 6 GB) was 20x.
A42: PHP versions
...

Sheet Add-ons
A1: Add-ons
A2: Prices are from your sheet. Blue = value you can change. Yellow = needs your decision.
A4: Add-on | B4: Size (GB) | C4: Price per month ($) | D4: $ per GB | E4: Decision | F4: Notes
A5: Offsite backup | B5: 5 | C5: 2 | D5: =C5/B5 -> 0.4 | E5: Keep
A6: Offsite backup | B6: 10 | C6: 3 | D6: =C6/B6 -> 0.3 | E6: Keep
A7: Offsite backup | B7: 30 | C7: 7 | D7: =C7/B7 -> 0.23333333 | E7: Keep
A8: Offsite backup | B8: 60 | C8: 13 | D8: =C8/B8 -> 0.21666667 | E8: Keep
A9: Offsite backup | B9: 100 | C9: 20 | D9: =C9/B9 -> 0.2 | E9: Keep
A10: Offsite backup | B10: 200 | C10: 35 | D10: =C10/B10 -> 0.175 | E10: Confirm size | F10: Your sheet says '20 gb' at $35, after 100 GB at $20. I have assumed 200 GB.
A11: Page Speed Boost | B11: n/a | C11: 10 | D11: n/a | E11: Keep
A12: Extra Layer Security | B12: n/a | C12: 10 | D12: n/a | E12: Define or remove | F12: Say what it adds beyond Imunify360 and DDoS protection, which every plan already has.
A13: Automatic malware scanning | B13: n/a | C13: 2 | D13: n/a | E13: Remove | F13: Imunify360 is included in every plan and already scans for malware.

Sheet Old to new
A1: Where each current plan lands
A2: Existing customers stay on their current plan and price. This shows which new plan a new buyer of each type would choose, matched on storage and resource type (my judgement; change column I and the prices follow). Current plans and prices: dronahost.com plan pages, read 11 Oct 2026.
A4: Current page | B4: Current plan | C4: Pay price ($/mo) | D4: Regular price ($/mo) | E4: Term (months) | F4: Websites | G4: Storage (GB) | H4: Other specs | I4: Nearest new plan | J4: New price ($/mo) | K4: Change vs pay price | L4: Change vs regular price | M4: Notes
A5: Cloud | B5: StartUp | C5: 1.1 | D5: 8.5 | E5: 12 | F5: 5 | G5: 20 | H5: 5 mailboxes | I5: Starter | J5: =IFERROR(INDEX(Plans!$B$8:$E$8,MATCH(I5,Plans!$B$4:$E$4,0)),Plans!$B$40) -> 14.99 | K5: =J5-C5 -> 13.89 | L5: =J5-D5 -> 6.49 | M5: Starter allows 2 sites against 5 today.
A6: Cloud | B6: Standard | C6: 2.33 | D6: 10.6 | E6: 12 | F6: Unlimited | G6: 30 | H6: 25 mailboxes | I6: Starter | J6: =IFERROR(INDEX(Plans!$B$8:$E$8,MATCH(I6,Plans!$B$4:$E$4,0)),Plans!$B$40) -> 14.99 | K6: =J6-C6 -> 12.66 | L6: =J6-D6 -> 4.39 | M6: Starter allows 2 sites and 10 mailboxes. Buyers with more sites need Growth or Pro.
A7: Cloud | B7: Premium | C7: 4.81 | D7: 16.6 | E7: 12 | F7: Unlimited | G7: 30 | H7: 25 mailboxes | I7: Starter | J7: =IFERROR(INDEX(Plans!$B$8:$E$8,MATCH(I7,Plans!$B$4:$E$4,0)),Plans!$B$40) -> 14.99 | K7: =J7-C7 -> 10.18 | L7: =J7-D7 -> -1.61 | M7: Starter allows 2 sites and 10 mailboxes. Buyers with more sites need Growth or Pro.
A8: Cloud | B8: Ultimate | C8: 8.71 | D8: 24.2 | E8: 12 | F8: Unlimited | G8: 50 | H8: 50 mailboxes, 3 GB RAM | I8: Starter | J8: =IFERROR(INDEX(Plans!$B$8:$E$8,MATCH(I8,Plans!$B$4:$E$4,0)),Plans!$B$40) -> 14.99 | K8: =J8-C8 -> 6.28 | L8: =J8-D8 -> -9.21 | M8: Same storage and RAM as Starter, but unlimited sites and 50 mailboxes today.
A9: WordPress | B9: StartUp | C9: 1.28 | D9: 10.8 | E9: 36 | F9: 5 | G9: 30 | H9: 5 mailboxes | I9: Starter | J9: =IFERROR(INDEX(Plans!$B$8:$E$8,MATCH(I9,Plans!$B$4:$E$4,0)),Plans!$B$40) -> 14.99 | K9: =J9-C9 -> 13.71 | L9: =J9-D9 -> 4.19 | M9: Starter allows 2 sites against 5 today.
A10: WordPress | B10: Standard | C10: 2.08 | D10: 12.9 | E10: 36 | F10: Unlimited | G10: 40 | H10: 25 mailboxes | I10: Starter | J10: =IFERROR(INDEX(Plans!$B$8:$E$8,MATCH(I10,Plans!$B$4:$E$4,0)),Plans!$B$40) -> 14.99 | K10: =J10-C10 -> 12.91 | L10: =J10-D10 -> 2.09 | M10: Starter allows 2 sites and 10 mailboxes. Buyers with more sites need Growth or Pro.
A11: WordPress | B11: Premium | C11: 3.97 | D11: 18.8 | E11: 36 | F11: Unlimited | G11: 60 | H11: 50 mailboxes | I11: Growth | J11: =IFERROR(INDEX(Plans!$B$8:$E$8,MATCH(I11,Plans!$B$4:$E$4,0)),Plans!$B$40) -> 21.99 | K11: =J11-C11 -> 18.02 | L11: =J11-D11 -> 3.19 | M11: Growth allows 5 sites and 25 mailboxes.
A12: WordPress | B12: Ultimate | C12: 8.09 | D12: 27.88 | E12: 36 | F12: Unlimited | G12: 100 | H12: 50 mailboxes | I12: Pro | J12: =IFERROR(INDEX(Plans!$B$8:$E$8,MATCH(I12,Plans!$B$4:$E$4,0)),Plans!$B$40) -> 49.99 | K12: =J12-C12 -> 41.9 | L12: =J12-D12 -> 22.11 | M12: Pro allows 25 sites.
A13: Business | B13: StartUp | C13: 10.73 | D13: 28.99 | E13: 36 | F13: Unlimited | G13: 50 | H13: 2 cores, 3 GB RAM | I13: Starter | J13: =IFERROR(INDEX(Plans!$B$8:$E$8,MATCH(I13,Plans!$B$4:$E$4,0)),Plans!$B$40) -> 14.99 | K13: =J13-C13 -> 4.26 | L13: =J13-D13 -> -14 | M13: Same storage, cores and RAM as Starter, but unlimited sites and mailboxes today.
A14: Business | B14: Enhance | C14: 11.07 | D14: 29.91 | E14: 36 | F14: Unlimited | G14: 80 | H14: 2 cores, 3 GB RAM | I14: Growth | J14: =IFERROR(INDEX(Plans!$B$8:$E$8,MATCH(I14,Plans!$B$4:$E$4,0)),Plans!$B$40) -> 21.99 | K14: =J14-C14 -> 10.92 | L14: =J14-D14 -> -7.92 | M14: Same storage as Growth, with 1 GB less RAM today.
A15: Business | B15: GrowBig | C15: 13.96 | D15: 39.89 | E15: 36 | F15: Unlimited | G15: 100 | H15: 2 cores, 4 GB RAM | I15: Pro | J15: =IFERROR(INDEX(Plans!$B$8:$E$8,MATCH(I15,Plans!$B$4:$E$4,0)),Plans!$B$40) -> 49.99 | K15: =J15-C15 -> 36.03 | L15: =J15-D15 -> 10.1 | M15: Pro has the same storage with more cores and RAM.
A16: Business | B16: Expand | C16: 26.27 | D16: 48.64 | E16: 12 | F16: Unlimited | G16: 160 | H16: 2 cores, 6 GB RAM | I16: Pro | J16: =IFERROR(INDEX(Plans!$B$8:$E$8,MATCH(I16,Plans!$B$4:$E$4,0)),Plans!$B$40) -> 49.99 | K16: =J16-C16 -> 23.72 | L16: =J16-D16 -> 1.35 | M16: Has 60 GB more than Pro; sell extra storage or move to Scale.
A17: VPS | B17: StartUp | C17: 34.19 | D17: 37.99 | E17: 12 | F17: n/a | G17: 20 | H17: 1 core, 2 GB RAM | I17: Pro | J17: =IFERROR(INDEX(Plans!$B$8:$E$8,MATCH(I17,Plans!$B$4:$E$4,0)),Plans!$B$40) -> 49.99 | K17: =J17-C17 -> 15.8 | L17: =J17-D17 -> 12 | M17: Pro has more of everything but is semi-dedicated.
A18: VPS | B18: Enhance | C18: 90 | D18: 150 | E18: 36 | F18: n/a | G18: 60 | H18: 2 cores, 4 GB RAM | I18: Scale | J18: =IFERROR(INDEX(Plans!$B$8:$E$8,MATCH(I18,Plans!$B$4:$E$4,0)),Plans!$B$40) -> 149.99 | K18: =J18-C18 -> 59.99 | L18: =J18-D18 -> -0.01 | M18: Pro ($49.99) has more cores, RAM and storage if semi-dedicated resources are acceptable.
A19: VPS | B19: GrowBig | C19: 118.16 | D19: 211 | E19: 36 | F19: n/a | G19: 80 | H19: 4 cores, 8 GB RAM | I19: Scale | J19: =IFERROR(INDEX(Plans!$B$8:$E$8,MATCH(I19,Plans!$B$4:$E$4,0)),Plans!$B$40) -> 149.99 | K19: =J19-C19 -> 31.83 | L19: =J19-D19 -> -61.01 | M19: Scale has twice the cores and nearly twice the storage.
A20: VPS | B20: Expend | C20: 156 | D20: 240 | E20: 36 | F20: n/a | G20: 160 | H20: 4 cores, 8 GB RAM | I20: Dedicated Core | J20: =IFERROR(INDEX(Plans!$B$8:$E$8,MATCH(I20,Plans!$B$4:$E$4,0)),Plans!$B$40) -> 300 | K20: =J20-C20 -> 144 | L20: =J20-D20 -> 60 | M20: Above Scale's storage, so this goes to the 'Talk to us' strip.
A22: Plans that cost a new buyer more than today's pay price | J22: =COUNTIF(K5:K20,">0") -> 16
A23: Plans that cost a new buyer more than today's regular price | J23: =COUNTIF(L5:L20,">0") -> 10

Sheet Open items
A1: Do or confirm before launch
A3: # | B3: Item | C3: Why it matters | D3: Owner | E3: Done
A4: 1 | B4: Remove the 'from $1.10' and 'SAVE 87%' pricing when the new plans go live | C4: Strike-through discount prices are the bargain signal the new positioning is meant to avoid.
A5: 2 | B5: Fix the proof on the site | C5: Testimonials have no business names, page titles say 2024, and the VPS page says 'Join XYZ Pre-Managed VPS Hosting' (read 11 Oct 2026). These matter more at $14.99 than at $1.10.
A6: 3 | B6: Fix the canonical tags on the plan pages | C6: When I read them on 11 Oct 2026, all four plan pages declared the homepage as canonical.
A7: 4 | B7: Set a 90-day review | C7: If paid orders fall by more than half and enquiries have not improved in quality, add a lower-priced single-site plan. Record today's monthly orders now so there is a baseline.
A8: 5 | B8: Confirm Starter's limit of 2 sites and 10 mailboxes | C8: Seven of today's plans map to Starter and all of them allow 5 or unlimited sites. See the Old to new tab.
A9: 6 | B9: Make Dedicated Core better than Scale on every limit | C9: Your sheet gave it 5 domains, 10 databases and 600% CPU, below Scale's unlimited and 800%.
A10: 7 | B10: Confirm backup retention of 7, 14, 30 and 30 days | C10: My suggestion, up from 1, 7, 7, 7 in your sheet. It uses more backup storage.
A11: 8 | B11: Confirm the 25% extra for monthly billing | C11: My suggestion; set on the Plans tab.
A12: 9 | B12: Load test each tier and fill in visits per month | C12: The Plans tab shows TBC. Small-business buyers compare on visits, not GB of bandwidth.
A13: 10 | B13: Confirm whether MySQL and Redis share the plan's RAM limit | C13: The PHP settings tab gives PHP workers 70% of RAM. If the database counts against the same limit, lower it or sites will run out of memory under load.
A14: 11 | B14: Measure real PHP worker size and a sensible workers-per-core figure | C14: pm.max_children depends on both; 80 to 110 MB and 10 per core are my estimates.
A15: 12 | B15: Confirm the largest offsite backup add-on is 200 GB | C15: Your sheet says 20 GB at $35.
... A17: 14 | B17: Move new accounts off PHP 8.2 | C17: Security support for 8.2 ends 31 Dec 2026 (php.net/supported-versions.php).
